[2022-12-15T06:17:54.217+0000] {taskinstance.py:1165} INFO - Dependencies all met for <TaskInstance: aws_to_bq.load scheduled__2022-12-15T00:14:18.922226+00:00 [queued]>
[2022-12-15T06:17:54.225+0000] {taskinstance.py:1165} INFO - Dependencies all met for <TaskInstance: aws_to_bq.load scheduled__2022-12-15T00:14:18.922226+00:00 [queued]>
[2022-12-15T06:17:54.225+0000] {taskinstance.py:1362} INFO - 
--------------------------------------------------------------------------------
[2022-12-15T06:17:54.226+0000] {taskinstance.py:1363} INFO - Starting attempt 2 of 2
[2022-12-15T06:17:54.226+0000] {taskinstance.py:1364} INFO - 
--------------------------------------------------------------------------------
[2022-12-15T06:17:54.239+0000] {taskinstance.py:1383} INFO - Executing <Task(BashOperator): load> on 2022-12-15 00:14:18.922226+00:00
[2022-12-15T06:17:54.242+0000] {standard_task_runner.py:55} INFO - Started process 226 to run task
[2022-12-15T06:17:54.244+0000] {standard_task_runner.py:82} INFO - Running: ['***', 'tasks', 'run', 'aws_to_bq', 'load', 'scheduled__2022-12-15T00:14:18.922226+00:00', '--job-id', '15', '--raw', '--subdir', 'DAGS_FOLDER/dags.py', '--cfg-path', '/tmp/tmpitlo_cem']
[2022-12-15T06:17:54.245+0000] {standard_task_runner.py:83} INFO - Job 15: Subtask load
[2022-12-15T06:17:54.293+0000] {task_command.py:376} INFO - Running <TaskInstance: aws_to_bq.load scheduled__2022-12-15T00:14:18.922226+00:00 [running]> on host 3d17ccc81221
[2022-12-15T06:17:54.345+0000] {taskinstance.py:1590} INFO - Exporting the following env vars:
AIRFLOW_CTX_DAG_EMAIL=lambobr1994@gmail.com
AIRFLOW_CTX_DAG_OWNER=***
AIRFLOW_CTX_DAG_ID=aws_to_bq
AIRFLOW_CTX_TASK_ID=load
AIRFLOW_CTX_EXECUTION_DATE=2022-12-15T00:14:18.922226+00:00
AIRFLOW_CTX_TRY_NUMBER=2
AIRFLOW_CTX_DAG_RUN_ID=scheduled__2022-12-15T00:14:18.922226+00:00
[2022-12-15T06:17:54.345+0000] {subprocess.py:63} INFO - Tmp dir root location: 
 /tmp
[2022-12-15T06:17:54.346+0000] {subprocess.py:75} INFO - Running command: ['/bin/bash', '-c', 'python3 /opt/***/python_scripts/bq_data_transfer.py']
[2022-12-15T06:17:54.353+0000] {subprocess.py:86} INFO - Output:
[2022-12-15T06:17:55.401+0000] {subprocess.py:93} INFO - Traceback (most recent call last):
[2022-12-15T06:17:55.402+0000] {subprocess.py:93} INFO -   File "/opt/***/python_scripts/bq_data_transfer.py", line 8, in <module>
[2022-12-15T06:17:55.402+0000] {subprocess.py:93} INFO -     transfer_client = bigquery_datatransfer.DataTransferServiceClient()
[2022-12-15T06:17:55.402+0000] {subprocess.py:93} INFO -   File "/home/***/.local/lib/python3.10/site-packages/google/cloud/bigquery_datatransfer_v1/services/data_transfer_service/client.py", line 467, in __init__
[2022-12-15T06:17:55.402+0000] {subprocess.py:93} INFO -     self._transport = Transport(
[2022-12-15T06:17:55.402+0000] {subprocess.py:93} INFO -   File "/home/***/.local/lib/python3.10/site-packages/google/cloud/bigquery_datatransfer_v1/services/data_transfer_service/transports/grpc.py", line 150, in __init__
[2022-12-15T06:17:55.402+0000] {subprocess.py:93} INFO -     super().__init__(
[2022-12-15T06:17:55.402+0000] {subprocess.py:93} INFO -   File "/home/***/.local/lib/python3.10/site-packages/google/cloud/bigquery_datatransfer_v1/services/data_transfer_service/transports/base.py", line 103, in __init__
[2022-12-15T06:17:55.402+0000] {subprocess.py:93} INFO -     credentials, _ = google.auth.default(
[2022-12-15T06:17:55.402+0000] {subprocess.py:93} INFO -   File "/home/***/.local/lib/python3.10/site-packages/google/auth/_default.py", line 646, in default
[2022-12-15T06:17:55.403+0000] {subprocess.py:93} INFO -     raise exceptions.DefaultCredentialsError(_HELP_MESSAGE)
[2022-12-15T06:17:55.403+0000] {subprocess.py:93} INFO - google.auth.exceptions.DefaultCredentialsError: Could not automatically determine credentials. Please set GOOGLE_APPLICATION_CREDENTIALS or explicitly create credentials and re-run the application. For more information, please see https://cloud.google.com/docs/authentication/getting-started
[2022-12-15T06:17:55.466+0000] {subprocess.py:97} INFO - Command exited with return code 1
[2022-12-15T06:17:55.474+0000] {taskinstance.py:1851} ERROR - Task failed with exception
Traceback (most recent call last):
  File "/home/airflow/.local/lib/python3.10/site-packages/airflow/operators/bash.py", line 196, in execute
    raise AirflowException(
airflow.exceptions.AirflowException: Bash command failed. The command returned a non-zero exit code 1.
[2022-12-15T06:17:55.477+0000] {taskinstance.py:1401} INFO - Marking task as FAILED. dag_id=aws_to_bq, task_id=load, execution_date=20221215T001418, start_date=20221215T061754, end_date=20221215T061755
[2022-12-15T06:17:55.493+0000] {standard_task_runner.py:100} ERROR - Failed to execute job 15 for task load (Bash command failed. The command returned a non-zero exit code 1.; 226)
[2022-12-15T06:17:55.500+0000] {local_task_job.py:159} INFO - Task exited with return code 1
[2022-12-15T06:17:55.520+0000] {taskinstance.py:2623} INFO - 0 downstream tasks scheduled from follow-on schedule check
